Workbook

Sheet Class List
A1: Name | B1: Date
B2: 46244 | C2: =B2+7 -> 46251 | D2: =C2+7 -> 46258 | E2: =D2+7 -> 46265 | F2: =E2+7 -> 46272 | G2: =F2+7 -> 46279 | H2: =G2+7 -> 46286 | I2: =H2+7 -> 46293 | J2: =I2+7 -> 46300 | ... BA2: =AZ2+7 -> 46601
A3: Abing, Jular
A4: Ambid, Marilyn | B4: 20 | C4: 20 | D4: 20 | E4: 20 | F4: 20 | G4: 20 | H4: 20 | I4: 20
A5: Antipolo, Jovelyn
A6: Arabit, Jarizel
A7: Barzaga, Maria Dolores | B7: 20 | C7: 20 | D7: 20 | E7: 20
A8: Batabat, Patricia Marianne
A9: Beato, Jhean Mirabel | B9: 20 | C9: 20 | D9: 20 | E9: 20 | F9: 20 | G9: 20
A10: Brucal, Charmaine | B10: 20 | C10: 20 | D10: 20 | E10: 20 | F10: 20 | G10: 20 | H10: 20 | I10: 20 | J10: 20 | K10: 20
A11: Caballero, Ma. Kryss Mae | B11: 20 | C11: 20 | D11: 20 | E11: 20 | F11: 20
A12: Cielo, Cristina | B12: 20 | C12: 20 | D12: 20 | E12: 20
A13: Clarito, Lee Andrei | B13: 20 | C13: 20 | D13: 20 | E13: 20 | F13: 20
A14: Corpuz, Shiela May
A15: Dela Cruz, Roslyn
A16: Diogracias, Irene Negrido
A17: Espeña, Mailyn Grace | B17: 20 | C17: 20 | D17: 20 | E17: 20
A18: Espinosa, Romeo JR.
A19: Faller, Chermelyn
A20: Gabelo, Dominic
A21: Ganaden, Daisy Lyn | B21: 20 | C21: 20 | D21: 20 | E21: 20
A22: Genovia, Ma. Ybony Angel | B22: 20 | C22: 20 | D22: 20 | E22: 20 | F22: 20 | G22: 20
A23: Grefiel, Princess Lou-ann Pauline
A24: Ignacio, Ver Nikolai RB | B24: 20 | C24: 20 | D24: 20 | E24: 20
A25: Jaya, Maria Jhienyrah
A26: Jones, Mary Grace | B26: 20 | C26: 20 | D26: 20 | E26: 20 | F26: 20 | G26: 20
A27: Lesanque, Danica Mai
A28: Mangiam, Jan France Sarah
A29: Masicampo, Joselito JR
A30: Mendiola, Romar
A31: Navarro, Nerie Ann | B31: 20 | C31: 10
A32: Nazareno, Cejhay
A33: Olidor, Rose Ann | B33: 20 | C33: 20 | D33: 20 | E33: 20
A34: Padrigano, Maria Cierene | B34: 20 | C34: 20 | D34: 20 | E34: 20 | F34: 20 | G34: 20 | H34: 20 | I34: 20 | J34: 20 | K34: 20
A35: Paredes, Brian | B35: 20 | C35: 20 | D35: 20 | E35: 20 | F35: 20 | G35: 20
A36: Rapol, Leanne Kim
A37: Reyes, Angelica | B37: 20 | C37: 20 | D37: 10
A38: Rioveros, Christine
A39: Samonte, Roshan | B39: 20 | C39: 20 | D39: 20 | E39: 20 | F39: 20 | G39: 20 | H39: 20 | I39: 20
A40: Siervo, Ashley Shereel | B40: 20 | C40: 20 | D40: 20 | E40: 20 | F40: 20 | G40: 20
...

Sheet Balance Sheet
A1: Date | B1: Funds | C1: Expenses | D1: Total
A2: August | B2: {=SUMPRODUCT((TEXT('Class List'!$B$2:$BA$2,"mmmm")=A2)*('Class List'!$B$44:$BA$44))} -> 4274 | C2: {=SUMPRODUCT((TEXT($C$20:$C$69,"mmmm")=A2)*($D$20:$D$69))} -> 515 | D2: =IF(AND(N(B2)=0, N(C2)=0), "", B2-C2) -> 3759
A3: September | B3: {=SUMPRODUCT((TEXT('Class List'!$B$2:$BA$2,"mmmm")=A3)*('Class List'!$B$44:$BA$44))} -> 560 | C3: {=SUMPRODUCT((TEXT($C$20:$C$69,"mmmm")=A3)*($D$20:$D$69))} -> 1749 | D3: =IF(AND(N(B3)=0, N(C3)=0), "", N(D2)+N(B3)-N(C3)) -> 2570
A4: October | B4: {=SUMPRODUCT((TEXT('Class List'!$B$2:$BA$2,"mmmm")=A4)*('Class List'!$B$44:$BA$44))} -> 80 | C4: {=SUMPRODUCT((TEXT($C$20:$C$69,"mmmm")=A4)*($D$20:$D$69))} -> 0 | D4: =IF(AND(N(B4)=0, N(C4)=0), "", N(D3)+N(B4)-N(C4)) -> 2650
A5: November | B5: {=SUMPRODUCT((TEXT('Class List'!$B$2:$BA$2,"mmmm")=A5)*('Class List'!$B$44:$BA$44))} -> 0 | C5: {=SUMPRODUCT((TEXT($C$20:$C$69,"mmmm")=A5)*($D$20:$D$69))} -> 0 | D5: =IF(AND(N(B5)=0, N(C5)=0), "", N(D4)+N(B5)-N(C5))
A6: December | B6: {=SUMPRODUCT((TEXT('Class List'!$B$2:$BA$2,"mmmm")=A6)*('Class List'!$B$44:$BA$44))} -> 0 | C6: {=SUMPRODUCT((TEXT($C$20:$C$69,"mmmm")=A6)*($D$20:$D$69))} -> 0 | D6: =IF(AND(N(B6)=0, N(C6)=0), "", N(D5)+N(B6)-N(C6))
A7: January | B7: {=SUMPRODUCT((TEXT('Class List'!$B$2:$BA$2,"mmmm")=A7)*('Class List'!$B$44:$BA$44))} -> 0 | C7: {=SUMPRODUCT((TEXT($C$20:$C$69,"mmmm")=A7)*($D$20:$D$69))} -> 0 | D7: =IF(AND(N(B7)=0, N(C7)=0), "", N(D6)+N(B7)-N(C7))
A8: February | B8: {=SUMPRODUCT((TEXT('Class List'!$B$2:$BA$2,"mmmm")=A8)*('Class List'!$B$44:$BA$44))} -> 0 | C8: {=SUMPRODUCT((TEXT($C$20:$C$69,"mmmm")=A8)*($D$20:$D$69))} -> 0 | D8: =IF(AND(N(B8)=0, N(C8)=0), "", N(D7)+N(B8)-N(C8))
A9: March | B9: {=SUMPRODUCT((TEXT('Class List'!$B$2:$BA$2,"mmmm")=A9)*('Class List'!$B$44:$BA$44))} -> 0 | C9: {=SUMPRODUCT((TEXT($C$20:$C$69,"mmmm")=A9)*($D$20:$D$69))} -> 0 | D9: =IF(AND(N(B9)=0, N(C9)=0), "", N(D8)+N(B9)-N(C9))
A10: April | B10: {=SUMPRODUCT((TEXT('Class List'!$B$2:$BA$2,"mmmm")=A10)*('Class List'!$B$44:$BA$44))} -> 0 | C10: {=SUMPRODUCT((TEXT($C$20:$C$69,"mmmm")=A10)*($D$20:$D$69))} -> 0 | D10: =IF(AND(N(B10)=0, N(C10)=0), "", N(D9)+N(B10)-N(C10))
A11: May | B11: {=SUMPRODUCT((TEXT('Class List'!$B$2:$BA$2,"mmmm")=A11)*('Class List'!$B$44:$BA$44))} -> 0 | C11: {=SUMPRODUCT((TEXT($C$20:$C$69,"mmmm")=A11)*($D$20:$D$69))} -> 0 | D11: =IF(AND(N(B11)=0, N(C11)=0), "", N(D10)+N(B11)-N(C11))
A12: June | B12: {=SUMPRODUCT((TEXT('Class List'!$B$2:$BA$2,"mmmm")=A12)*('Class List'!$B$44:$BA$44))} -> 0 | C12: {=SUMPRODUCT((TEXT($C$20:$C$69,"mmmm")=A12)*($D$20:$D$69))} -> 0 | D12: =IF(AND(N(B12)=0, N(C12)=0), "", N(D11)+N(B12)-N(C12))
A13: July | B13: {=SUMPRODUCT((TEXT('Class List'!$B$2:$BA$2,"mmmm")=A13)*('Class List'!$B$44:$BA$44))} -> 0 | C13: {=SUMPRODUCT((TEXT($C$20:$C$69,"mmmm")=A13)*($D$20:$D$69))} -> 0 | D13: =IF(AND(N(B13)=0, N(C13)=0), "", N(D12)+N(B13)-N(C13))
C14: {=SUMPRODUCT((TEXT($C$21:$C$50,"mmmm")=A14)*($D$21:$D$50))} -> 0 | D14: =IF(AND(N(B14)=0, N(C14)=0), "", MAX(D$2:D13)+N(B14)-N(C14))
C15: {=SUMPRODUCT((TEXT($C$21:$C$50,"mmmm")=A15)*($D$21:$D$50))} -> 0 | D15: =IF(AND(N(B15)=0, N(C15)=0), "", MAX(D$2:D14)+N(B15)-N(C15))
C16: {=SUMPRODUCT((TEXT($C$21:$C$50,"mmmm")=A16)*($D$21:$D$50))} -> 0 | D16: =IF(AND(N(B16)=0, N(C16)=0), "", MAX(D$2:D15)+N(B16)-N(C16))
A18: EXPENSE LOG | E18: =HYPERLINK("https://drive.google.com/your-link-here","Copy Paste Link") -> Copy Paste Link
A19: No. | B19: Description | C19: Date Incurred | D19: Amount | E19: Receipts
A20: 1 | B20: Cake | C20: 46260 | D20: 329
A21: 2 | B21: Snack Prof (PSN21) | C21: 46246 | D21: 85
A22: 3 | B22: Snack Prof (PSN21) | C22: 46261 | D22: 101
A23: 4 | B23: Snack Prof (PSN21) | C23: 46266 | D23: 420
A24: 5 | B24: Snack Prof (PSN11) | C24: 46270 | D24: 429
A25: 6 | B25: 2 Polo Shirt Prof | C25: 46270 | D25: 540
A26: 7 | B26: Snack Prof (PSN21) | C26: 46281 | D26: 360
A27: 8
A28: 9
A29: 10
A30: 11
A31: 12
A32: 13
A33: 14
A34: 15
A35: 16
A36: 17
A37: 18
A38: 19
... A69: 50

Sheet Events
A1: Name | B1: PSPO | C1: General Assembly | D1: Prof Polo | E1: Polo Shirts | F1: Token (CLAC)
B2: 46260 | C2: 46269 | D2: 46270 | E2: 46271
A3: Abing, Jular | B3: 50 | C3: 150 | D3: 150
A4: Ambid, Marilyn | B4: 50 | C4: 150 | D4: 150 | E4: 350 | F4: 20
A5: Antipolo, Jovelyn | B5: 50 | C5: 150 | D5: 150 | E5: 350
A6: Arabit, Jarizel | B6: 50 | C6: 150 | D6: 150
A7: Barzaga, Maria Dolores | B7: 50 | C7: 150 | D7: 150 | E7: 350 | F7: 20
A8: Batabat, Patricia Marianne | B8: 50 | C8: 150 | D8: 150 | E8: 700 | F8: 20
A9: Beato, Jhean Mirabel | B9: 50 | C9: 150 | D9: 150 | E9: 350 | F9: 20
A10: Brucal, Charmaine | B10: 50 | C10: 150 | D10: 150 | F10: 20
A11: Caballero, Ma. Kryss Mae | B11: 50 | C11: 150 | D11: 150 | F11: 20
A12: Cielo, Cristina | B12: 50 | C12: 150 | D12: 150
A13: Clarito, Lee Andrei | B13: 50 | C13: 150 | D13: 150
A14: Corpuz, Shiela May | B14: 50 | C14: 150 | D14: 150 | F14: 20
A15: Dela Cruz, Roslyn | B15: 50 | C15: 150 | D15: 150 | E15: 350
A16: Diogracias, Irene Negrido | B16: 50 | C16: 150 | D16: 150 | E16: 350
A17: Espeña, Mailyn Grace | B17: 50 | C17: 150 | D17: 150 | F17: 20
A18: Espinosa, Romeo JR. | B18: 50 | C18: 150 | D18: 150 | E18: 350
A19: Faller, Chermelyn | B19: 50 | C19: 150 | D19: 150
A20: Gabelo, Dominic | B20: 50 | C20: 150 | D20: 150
A21: Ganaden, Daisy Lyn | B21: 50 | C21: 150 | D21: 150
A22: Genovia, Ma. Ybony Angel | B22: 50 | C22: 150 | D22: 150 | F22: 20
A23: Grefiel, Princess Lou-ann Pauline | B23: 50 | C23: 150 | D23: 150
A24: Ignacio, Ver Nikolai RB | B24: 50 | C24: 150 | D24: 150
A25: Jaya, Maria Jhienyrah | B25: 50 | C25: 150 | D25: 150 | E25: 350
A26: Jones, Mary Grace | B26: 50 | C26: 150 | D26: 150 | F26: 20
A27: Lesanque, Danica Mai | B27: 50 | C27: 150 | D27: 150 | E27: 350
A28: Mangiam, Jan France Sarah | B28: 50 | C28: 150 | D28: 150 | E28: 350
A29: Masicampo, Joselito JR | B29: 50 | C29: 150 | D29: 150
A30: Mendiola, Romar | B30: 50 | C30: 150 | D30: 150
A31: Navarro, Nerie Ann | B31: 50 | C31: 150 | D31: 150 | F31: 20
A32: Nazareno, Cejhay | B32: 50 | C32: 150 | D32: 150 | E32: 350
A33: Olidor, Rose Ann | B33: 50 | C33: 150 | D33: 150
A34: Padrigano, Maria Cierene | B34: 50 | C34: 150 | D34: 150 | F34: 50
A35: Paredes, Brian | B35: 50 | C35: 150 | D35: 150 | F35: 20
A36: Rapol, Leanne Kim | B36: 50 | C36: 150 | D36: 150 | E36: 350 | F36: 20
A37: Reyes, Angelica | B37: 50 | C37: 150 | D37: 150
A38: Rioveros, Christine | B38: 50 | C38: 150 | D38: 150 | E38: 350 | F38: 20
A39: Samonte, Roshan | B39: 50 | C39: 150 | D39: 150 | E39: 350 | F39: 20
A40: Siervo, Ashley Shereel | B40: 50 | C40: 150 | D40: 150 | F40: 20
...

Sheet Event Balance Sheet
A1: Event | B1: Date | C1: Funds | D1: Expenses | E1: Total
A2: =IF(Events!B1="","",Events!B1) -> PSPO | B2: =IF(Events!B2="","",Events!B2) -> 46260 | C2: =Events!B44 -> 2050 | D2: =SUMIFS($E$15:$E$44,$D$15:$D$44,"="&B2) -> 2050 | E2: =C2-D2 -> 0
A3: =IF(Events!C1="","",Events!C1) -> General Assembly | B3: =IF(Events!C2="","",Events!C2) -> 46269 | C3: =Events!C44 -> 6150 | D3: =SUMIFS($E$15:$E$44,$D$15:$D$44,"="&B3) -> 6150 | E3: =IF(A3="", "", E2+C3-D3) -> 0
A4: =IF(Events!D1="","",Events!D1) -> Prof Polo | B4: =IF(Events!D2="","",Events!D2) -> 46270 | C4: =Events!D44 -> 6150 | D4: =SUMIFS($E$15:$E$44,$D$15:$D$44,"="&B4) -> 6150 | E4: =IF(A4="", "", E3+C4-D4) -> 0
A5: =IF(Events!E1="","",Events!E1) -> Polo Shirts | B5: =IF(Events!E2="","",Events!E2) -> 46271 | C5: =Events!E44 -> 6300 | D5: =SUMIFS($E$15:$E$44,$D$15:$D$44,"="&B5) -> 6300 | E5: =IF(A5="", "", E4+C5-D5) -> 0
A6: =IF(Events!F1="","",Events!F1) -> Token (CLAC) | B6: =IF(Events!F2="","",Events!F2) | C6: =Events!F44 -> 370 | D6: =SUMIFS($E$15:$E$44,$D$15:$D$44,"="&B6) -> 0 | E6: =IF(A6="", "", E5+C6-D6) -> 370
A7: =IF(Events!G1="","",Events!G1) | B7: =IF(Events!G2="","",Events!G2) | C7: =Events!G44 -> 0 | D7: =SUMIFS($E$15:$E$44,$D$15:$D$44,"="&B7) -> 0 | E7: =IF(A7="", "", E6+C7-D7)
A8: =IF(Events!H1="","",Events!H1) | B8: =IF(Events!H2="","",Events!H2) | C8: =Events!H44 -> 0 | D8: =SUMIFS($E$15:$E$44,$D$15:$D$44,"="&B8) -> 0 | E8: =IF(A8="", "", E7+C8-D8)
A9: =IF(Events!I1="","",Events!I1) | B9: =IF(Events!I2="","",Events!I2) | C9: =Events!I44 -> 0 | D9: =SUMIFS($E$15:$E$44,$D$15:$D$44,"="&B9) -> 0 | E9: =IF(A9="", "", E8+C9-D9)
A10: =IF(Events!J1="","",Events!J1) | B10: =IF(Events!J2="","",Events!J2) | C10: =Events!J44 -> 0 | D10: =SUMIFS($E$15:$E$44,$D$15:$D$44,"="&B10) -> 0 | E10: =IF(A10="", "", E9+C10-D10)
A11: =IF(Events!K1="","",Events!K1) | B11: =IF(Events!K2="","",Events!K2) | C11: =Events!K44 -> 0 | D11: =SUMIFS($E$15:$E$44,$D$15:$D$44,"="&B11) -> 0 | E11: =IF(A11="", "", E10+C11-D11)
A13: EXPENSE LOG
A14: No. | B14: Description | C14: Event | D14: Date Incurred | E14: Amount | F14: =HYPERLINK("https://drive.google.com/your-link-here","Copy Paste Link") -> Copy Paste Link
A15: 1 | B15: Food and Token | C15: PSPO | D15: 46260 | E15: 2050 | F15: Receipts
A16: 2 | B16: Downpayment | C16: General Assembly | D16: 46269 | E16: 4550
A17: 3 | B17: Downpayment | C17: Polo for Prof | D17: 46270 | E17: 2700
A18: 4 | B18: Balance | C18: Polo for Prof | D18: 46270 | E18: 3450
A19: 5 | B19: Students and Prof | C19: Polo Shirts | D19: 46271 | E19: 6300
A20: 6 | B20: Balance | C20: General Assembly | D20: 46269 | E20: 1600
A21: 7
A22: 8
A23: 9
A24: 10
A25: 11
A26: 12
A27: 13
A28: 14
A29: 15
A30: 16
A31: 17
A32: 18
... A44: 30
